Workbook

Sheet Nome dos Participantes

Sheet Feriados
A1: Data | B1: Dia da Semana | C1: Feriado
A2: 36892 | B2: segunda-feira | C2: Confraternização Universal
A3: 36948 | B3: segunda-feira | C3: Carnaval
A4: 36949 | B4: terça-feira | C4: Carnaval
A5: 36994 | B5: sexta-feira | C5: Paixão de Cristo
A6: 37002 | B6: sábado | C6: Tiradentes
A7: 37012 | B7: terça-feira | C7: Dia do Trabalho
A8: 37056 | B8: quinta-feira | C8: Corpus Christi
A9: 37141 | B9: sexta-feira | C9: Independência do Brasil
A10: 37176 | B10: sexta-feira | C10: Nossa Sr.a Aparecida - Padroeira do Brasil
A11: 37197 | B11: sexta-feira | C11: Finados
A12: 37210 | B12: quinta-feira | C12: Proclamação da República
A13: 37250 | B13: terça-feira | C13: Natal
... A1265: 73044 | B1265: sexta-feira | C1265: Natal
A1267: Fonte: ANBIMA
A1269: 1) De acordo com a Resolução n º 2.516, a partir do ano 2000, a quinta-feira da Semana Santa foi considerada dia útil. Esta mesma Resolução dispensou as instituições financeiras do cumprimento do horário mínimo de funcionamento, desde que informem ao público.
A1271: 2) A lei nº 9.504/97 estabeleceu que, em ano eleitoral, o 1º turno das eleições será realizado no primeiro domingo de outubro; e o 2º turno, quando houver, no último domingo do referido mês.
A1273: 3) De acordo com a Resolução nº 2.596/99, no último dia útil do ano não haverá atendimento ao público.
A1275: 4) Esta listagem não inclui os feriados municipais, eleições e o último dia do ano. O critério adotado foi o de indicar os feriados em que não há sensibilização das Reservas Bancárias.

Sheet Equivalência de Capitais
B1: TAXA DE JUROS | C1: 0.1635 | F1: Parcela igual | G1: TAXA DE JUROS | H1: =C1 -> 0.1635
B2: DATA BASE | C2: 46105 | F2: =(C3-SUM(J7,J9:J12,J14:J21,J23:J27,J29:J34,J36:J42,J44:J47))/F9 -> 230995.24 | G2: DATA BASE | H2: =C2 -> 46105
B3: VALOR ATUALIZADO | C3: =SUM(E7:E43) -> 6648042.5 | F3: =(1+$H$1)^(I8/365) -> 0.96775546 | G3: VALOR ATUALIZADO | H3: =SUM(J7:J47) -> 6648042.5
F4: =(1+$H$1)^(I13/365) -> 0.83487389
B5: PLANO ORIGINAL | F5: =(1+$H$1)^(I22/365) -> 0.59931556 | G5: PLANO ALTERNATIVO
B6: Vencimento | C6: Obrigações | D6: Var Dias | E6: Valor Atualizado | F6: =(1+$H$1)^(I28/365) -> 0.44473856 | G6: Vencimento | H6: Obrigações | I6: Var Dias | J6: Valor Atualizado
B7: 45131 | C7: 158682.46 | D7: =$C$2-B7 -> 974 | E7: =C7*(1+$C$1)^(D7/365) -> 237698.3 | F7: =(1+$H$1)^(I35/365) -> 0.34933245 | G7: 46156 | H7: 265586.79 | I7: =$H$2-G7 -> -51 | J7: =H7*(1+$H$1)^(I7/365) -> 260026.25
B8: 45173 | C8: 168866.43 | D8: =$C$2-B8 -> 932 | E8: =C8*(1+$C$1)^(D8/365) -> 248583.81 | F8: =(1+$H$1)^(I43/365) -> 0.25464803 | G8: 46184 | H8: =$F$2 -> 230995.24 | I8: =$H$2-G8 -> -79 | J8: =H8*(1+$H$1)^(I8/365) -> 223546.9
B9: 45247 | C9: 173676.91 | D9: =$C$2-B9 -> 858 | E9: =C9*(1+$C$1)^(D9/365) -> 247935.17 | F9: =SUM(F3:F8) -> 3.450664 | G9: 46252 | H9: 280581.24 | I9: =$H$2-G9 -> -147 | J9: =H9*(1+$H$1)^(I9/365) -> 263980.53
B10: 45331 | C10: 186451.47 | D10: =$C$2-B10 -> 774 | E10: =C10*(1+$C$1)^(D10/365) -> 257055.32 | G10: 46286 | H10: 288821.06 | I10: =$H$2-G10 -> -181 | J10: =H10*(1+$H$1)^(I10/365) -> 267926.66
B11: 45387 | C11: 178529.25 | D11: =$C$2-B11 -> 718 | E11: =C11*(1+$C$1)^(D11/365) -> 240480.56 | G11: 46344 | H11: 285433.58 | I11: =$H$2-G11 -> -239 | J11: =H11*(1+$H$1)^(I11/365) -> 258488.72
B12: 45482 | C12: 192409.21 | D12: =$C$2-B12 -> 623 | E12: =C12*(1+$C$1)^(D12/365) -> 249160.49 | G12: 46440 | H12: 294778.8 | I12: =$H$2-G12 -> -335 | J12: =H12*(1+$H$1)^(I12/365) -> 256528.32
B13: 45588 | C13: 196114.29 | D13: =$C$2-B13 -> 517 | E13: =C13*(1+$C$1)^(D13/365) -> 243031.9 | G13: 46540 | H13: =$F$2 -> 230995.24 | I13: =$H$2-G13 -> -435 | J13: =H13*(1+$H$1)^(I13/365) -> 192851.89
B14: 45653 | C14: 197261.55 | D14: =$C$2-B14 -> 452 | E14: =C14*(1+$C$1)^(D14/365) -> 237949.42 | G14: 46608 | H14: 299631.14 | I14: =$H$2-G14 -> -503 | J14: =H14*(1+$H$1)^(I14/365) -> 243195.46
B15: 45797 | C15: 202072.03 | D15: =$C$2-B15 -> 308 | E15: =C15*(1+$C$1)^(D15/365) -> 229616.04 | G15: 46745 | H15: 308976.36 | I15: =$H$2-G15 -> -640 | J15: =H15*(1+$H$1)^(I15/365) -> 236923.89
B16: 45849 | C16: 214846.59 | D16: =$C$2-B16 -> 256 | E16: =C16*(1+$C$1)^(D16/365) -> 238921.39 | G16: 46801 | H16: 317216.18 | I16: =$H$2-G16 -> -696 | J16: =H16*(1+$H$1)^(I16/365) -> 237655.98
B17: 45992 | C17: 206924.37 | D17: =$C$2-B17 -> 113 | E17: =C17*(1+$C$1)^(D17/365) -> 216856.38 | G17: 46947 | H17: 313828.7 | I17: =$H$2-G17 -> -842 | J17: =H17*(1+$H$1)^(I17/365) -> 221299.03
B18: 46066 | C18: 220804.33 | D18: =$C$2-B18 -> 39 | E18: =C18*(1+$C$1)^(D18/365) -> 224406.11 | G18: 47021 | H18: 319173.92 | I18: =$H$2-G18 -> -916 | J18: =H18*(1+$H$1)^(I18/365) -> 218263.34
B19: 46122 | C19: 224509.41 | D19: =$C$2-B19 -> -17 | E19: =C19*(1+$C$1)^(D19/365) -> 222931.51 | G19: 47078 | H19: 320339.78 | I19: =$H$2-G19 -> -973 | J19: =H19*(1+$H$1)^(I19/365) -> 213940.94
B20: 46286 | C20: 218326.97 | D20: =$C$2-B20 -> -181 | E20: =C20*(1+$C$1)^(D20/365) -> 202532.38 | G20: 47242 | H20: 320696.56 | I20: =$H$2-G20 -> -1137 | J20: =H20*(1+$H$1)^(I20/365) -> 200090.97
B21: 46353 | C21: 218441.44 | D21: =$C$2-B21 -> -248 | E21: =C21*(1+$C$1)^(D21/365) -> 197083.34 | G21: 47308 | H21: 325345.77 | I21: =$H$2-G21 -> -1203 | J21: =H21*(1+$H$1)^(I21/365) -> 197508.76
B22: 46391 | C22: 219316.97 | D22: =$C$2-B22 -> -286 | E22: =C22*(1+$C$1)^(D22/365) -> 194778.14 | G22: 47339 | H22: =$F$2 -> 230995.24 | I22: =$H$2-G22 -> -1234 | J22: =H22*(1+$H$1)^(I22/365) -> 138439.04
B23: 46525 | C23: 217426.99 | D23: =$C$2-B23 -> -420 | E23: =C23*(1+$C$1)^(D23/365) -> 182657.31 | G23: 47480 | H23: 324331.32 | I23: =$H$2-G23 -> -1375 | J23: =H23*(1+$H$1)^(I23/365) -> 183332.22
B24: 46668 | C24: 229852.2 | D24: =$C$2-B24 -> -563 | E24: =C24*(1+$C$1)^(D24/365) -> 181972.71 | G24: 47624 | H24: 332221.79 | I24: =$H$2-G24 -> -1519 | J24: =H24*(1+$H$1)^(I24/365) -> 176901.63
B25: 46813 | C25: 233206.78 | D25: =$C$2-B25 -> -708 | E25: =C25*(1+$C$1)^(D25/365) -> 173849.08 | G25: 47764 | H25: 340111.11 | I25: =$H$2-G25 -> -1659 | J25: =H25*(1+$H$1)^(I25/365) -> 170883.08
B26: 46881 | C26: 234851.87 | D26: =$C$2-B26 -> -776 | E26: =C26*(1+$C$1)^(D26/365) -> 170205.22 | G26: 47830 | H26: 338012.78 | I26: =$H$2-G26 -> -1725 | J26: =H26*(1+$H$1)^(I26/365) -> 165241.59
B27: 46938 | C27: 238207.19 | D27: =$C$2-B27 -> -833 | E27: =C27*(1+$C$1)^(D27/365) -> 168602.25 | G27: 47890 | H27: 337221.46 | I27: =$H$2-G27 -> -1785 | J27: =H27*(1+$H$1)^(I27/365) -> 160801.67
B28: 47102 | C28: 238152.04 | D28: =$C$2-B28 -> -997 | E28: =C28*(1+$C$1)^(D28/365) -> 157475.49 | G28: 48058 | H28: =$F$2 -> 230995.24 | I28: =$H$2-G28 -> -1953 | J28: =H28*(1+$H$1)^(I28/365) -> 102732.49
B29: 47172 | C29: 241507.09 | D29: =$C$2-B29 -> -1067 | E29: =C29*(1+$C$1)^(D29/365) -> 155122.86 | G29: 48123 | H29: 340521.63 | I29: =$H$2-G29 -> -2018 | J29: =H29*(1+$H$1)^(I29/365) -> 147413.64
B30: 47210 | C30: 253931.71 | D30: =$C$2-B30 -> -1105 | E30: =C30*(1+$C$1)^(D30/365) -> 160552.09 | G30: 48156 | H30: 348411.42 | I30: =$H$2-G30 -> -2051 | J30: =H30*(1+$H$1)^(I30/365) -> 148778.21
B31: 47336 | C31: 246507.19 | D31: =$C$2-B31 -> -1231 | E31: =C31*(1+$C$1)^(D31/365) -> 147919.59 | G31: 48290 | H31: 356301.3 | I31: =$H$2-G31 -> -2185 | J31: =H31*(1+$H$1)^(I31/365) -> 143919.62
B32: 47501 | C32: 258931.85 | D32: =$C$2-B32 -> -1396 | E32: =C32*(1+$C$1)^(D32/365) -> 145094.71 | G32: 48452 | H32: 353411.52 | I32: =$H$2-G32 -> -2347 | J32: =H32*(1+$H$1)^(I32/365) -> 133473.12
B33: 47564 | C33: 249806.9 | D33: =$C$2-B33 -> -1459 | E33: =C33*(1+$C$1)^(D33/365) -> 136370.07 | G33: 48515 | H33: 361301.44 | I33: =$H$2-G33 -> -2410 | J33: =H33*(1+$H$1)^(I33/365) -> 132932.56
B34: 47609 | C34: 262231.75 | D34: =$C$2-B34 -> -1504 | E34: =C34*(1+$C$1)^(D34/365) -> 140504.98 | G34: 48561 | H34: 359297.32 | I34: =$H$2-G34 -> -2456 | J34: =H34*(1+$H$1)^(I34/365) -> 129696.21
B35: 47683 | C35: 245514.63 | D35: =$C$2-B35 -> -1578 | E35: =C35*(1+$C$1)^(D35/365) -> 127570.53 | G35: 48640 | H35: =$F$2 -> 230995.24 | I35: =$H$2-G35 -> -2535 | J35: =H35*(1+$H$1)^(I35/365) -> 80694.131
B36: 47795 | C36: 257938.92 | D36: =$C$2-B36 -> -1690 | E36: =C36*(1+$C$1)^(D36/365) -> 127940.93 | G36: 48750 | H36: 364601.34 | I36: =$H$2-G36 -> -2645 | J36: =H36*(1+$H$1)^(I36/365) -> 121685.04
B37: 47865 | C37: 250514.33 | D37: =$C$2-B37 -> -1760 | E37: =C37*(1+$C$1)^(D37/365) -> 120701.44 | G37: 48816 | H37: 352418.96 | I37: =$H$2-G37 -> -2711 | J37: =H37*(1+$H$1)^(I37/365) -> 114442.19
B38: 47952 | C38: 262939.25 | D38: =$C$2-B38 -> -1847 | E38: =C38*(1+$C$1)^(D38/365) -> 122196.7 | G38: 48904 | H38: 360308.51 | I38: =$H$2-G38 -> -2799 | J38: =H38*(1+$H$1)^(I38/365) -> 112809.44
B39: 48127 | C39: 253813.86 | D39: =$C$2-B39 -> -2022 | E39: =C39*(1+$C$1)^(D39/365) -> 109695.18 | G39: 49079 | H39: 357418.66 | I39: =$H$2-G39 -> -2974 | J39: =H39*(1+$H$1)^(I39/365) -> 104067.78
B40: 48191 | C40: 266238.43 | D40: =$C$2-B40 -> -2086 | E40: =C40*(1+$C$1)^(D40/365) -> 112049.86 | G40: 49138 | H40: 359297.32 | I40: =$H$2-G40 -> -3033 | J40: =H40*(1+$H$1)^(I40/365) -> 102085.09
...

Sheet Amortização de Dívidas
A1: TABELA PRICE | G1: SISTEMA DE AMORTIZAÇÃO CONSTANTE - SAC
B2: Data de Liquidação | C2: 46105 | D2: Número de Parcelas | E2: 60 | H2: Data de Liquidação | I2: 46105 | J2: Número de Parcelas | K2: 60
B3: Valor Empréstimo | C3: 600000 | D3: Taxa de Juro | E3: 0.0115 | H3: Valor Empréstimo | I3: 600000 | J3: Taxa de Juro | K3: 0.0115
A5: Data | B5: Prestação | C5: Juros | D5: Amortização | E5: Saldo Devedor | G5: Data | H5: Prestação | I5: Juros | J5: Amortização | K5: Saldo Devedor
A8: =WORKDAY.INTL(EDATE($C$2,1)-1,1,1,Feriados!$A$2:$A$1275) -> 46136 | B8: =-PMT($E$3,$E$2,$C$3) -> 13898.816 | C8: =$C$3*$E$3 -> 6900 | D8: =B8-C8 -> 6998.8161 | E8: =$C$3-D8 -> 593001.18 | G8: =WORKDAY.INTL(EDATE($I$2,1)-1,1,1,Feriados!$A$2:$A$1275) -> 46136 | H8: =I8+J8 -> 16900 | I8: =$I$3*$K$3 -> 6900 | J8: =$I$3/$K$2 -> 10000 | K8: =$I$3-J8 -> 590000
A9: =WORKDAY.INTL(EDATE($C$2,2)-1,1,1,Feriados!$A$2:$A$1275) -> 46167 | B9: =$B$8 -> 13898.816 | C9: =E8*$E$3 -> 6819.5136 | D9: =B9-C9 -> 7079.3025 | E9: =MAX(0,E8-D9) -> 585921.88 | G9: =WORKDAY.INTL(EDATE($I$2,2)-1,1,1,Feriados!$A$2:$A$1275) -> 46167 | H9: =I9+J9 -> 16785 | I9: =K8*$K$3 -> 6785 | J9: =$J$8 -> 10000 | K9: =MAX(0,K8-J9) -> 580000
A10: =WORKDAY.INTL(EDATE($C$2,3)-1,1,1,Feriados!$A$2:$A$1275) -> 46197 | B10: =$B$8 -> 13898.816 | C10: =E9*$E$3 -> 6738.1016 | D10: =B10-C10 -> 7160.7145 | E10: =MAX(0,E9-D10) -> 578761.17 | G10: =WORKDAY.INTL(EDATE($I$2,3)-1,1,1,Feriados!$A$2:$A$1275) -> 46197 | H10: =I10+J10 -> 16670 | I10: =K9*$K$3 -> 6670 | J10: =$J$8 -> 10000 | K10: =MAX(0,K9-J10) -> 570000
A11: =WORKDAY.INTL(EDATE($C$2,4)-1,1,1,Feriados!$A$2:$A$1275) -> 46227 | B11: =$B$8 -> 13898.816 | C11: =E10*$E$3 -> 6655.7534 | D11: =B11-C11 -> 7243.0627 | E11: =MAX(0,E10-D11) -> 571518.1 | G11: =WORKDAY.INTL(EDATE($I$2,4)-1,1,1,Feriados!$A$2:$A$1275) -> 46227 | H11: =I11+J11 -> 16555 | I11: =K10*$K$3 -> 6555 | J11: =$J$8 -> 10000 | K11: =MAX(0,K10-J11) -> 560000
A12: =WORKDAY.INTL(EDATE($C$2,5)-1,1,1,Feriados!$A$2:$A$1275) -> 46258 | B12: =$B$8 -> 13898.816 | C12: =E11*$E$3 -> 6572.4582 | D12: =B12-C12 -> 7326.3579 | E12: =MAX(0,E11-D12) -> 564191.75 | G12: =WORKDAY.INTL(EDATE($I$2,5)-1,1,1,Feriados!$A$2:$A$1275) -> 46258 | H12: =I12+J12 -> 16440 | I12: =K11*$K$3 -> 6440 | J12: =$J$8 -> 10000 | K12: =MAX(0,K11-J12) -> 550000
A13: =WORKDAY.INTL(EDATE($C$2,6)-1,1,1,Feriados!$A$2:$A$1275) -> 46289 | B13: =$B$8 -> 13898.816 | C13: =E12*$E$3 -> 6488.2051 | D13: =B13-C13 -> 7410.611 | E13: =MAX(0,E12-D13) -> 556781.14 | G13: =WORKDAY.INTL(EDATE($I$2,6)-1,1,1,Feriados!$A$2:$A$1275) -> 46289 | H13: =I13+J13 -> 16325 | I13: =K12*$K$3 -> 6325 | J13: =$J$8 -> 10000 | K13: =MAX(0,K12-J13) -> 540000
A14: =WORKDAY.INTL(EDATE($C$2,7)-1,1,1,Feriados!$A$2:$A$1275) -> 46321 | B14: =$B$8 -> 13898.816 | C14: =E13*$E$3 -> 6402.9831 | D14: =B14-C14 -> 7495.833 | E14: =MAX(0,E13-D14) -> 549285.3 | G14: =WORKDAY.INTL(EDATE($I$2,7)-1,1,1,Feriados!$A$2:$A$1275) -> 46321 | H14: =I14+J14 -> 16210 | I14: =K13*$K$3 -> 6210 | J14: =$J$8 -> 10000 | K14: =MAX(0,K13-J14) -> 530000
A15: =WORKDAY.INTL(EDATE($C$2,8)-1,1,1,Feriados!$A$2:$A$1275) -> 46350 | B15: =$B$8 -> 13898.816 | C15: =E14*$E$3 -> 6316.781 | D15: =B15-C15 -> 7582.0351 | E15: =MAX(0,E14-D15) -> 541703.27 | G15: =WORKDAY.INTL(EDATE($I$2,8)-1,1,1,Feriados!$A$2:$A$1275) -> 46350 | H15: =I15+J15 -> 16095 | I15: =K14*$K$3 -> 6095 | J15: =$J$8 -> 10000 | K15: =MAX(0,K14-J15) -> 520000
A16: =WORKDAY.INTL(EDATE($C$2,9)-1,1,1,Feriados!$A$2:$A$1275) -> 46380 | B16: =$B$8 -> 13898.816 | C16: =E15*$E$3 -> 6229.5876 | D16: =B16-C16 -> 7669.2285 | E16: =MAX(0,E15-D16) -> 534034.04 | G16: =WORKDAY.INTL(EDATE($I$2,9)-1,1,1,Feriados!$A$2:$A$1275) -> 46380 | H16: =I16+J16 -> 15980 | I16: =K15*$K$3 -> 5980 | J16: =$J$8 -> 10000 | K16: =MAX(0,K15-J16) -> 510000
A17: =WORKDAY.INTL(EDATE($C$2,10)-1,1,1,Feriados!$A$2:$A$1275) -> 46412 | B17: =$B$8 -> 13898.816 | C17: =E16*$E$3 -> 6141.3914 | D17: =B17-C17 -> 7757.4247 | E17: =MAX(0,E16-D17) -> 526276.61 | G17: =WORKDAY.INTL(EDATE($I$2,10)-1,1,1,Feriados!$A$2:$A$1275) -> 46412 | H17: =I17+J17 -> 15865 | I17: =K16*$K$3 -> 5865 | J17: =$J$8 -> 10000 | K17: =MAX(0,K16-J17) -> 500000
A18: =WORKDAY.INTL(EDATE($C$2,11)-1,1,1,Feriados!$A$2:$A$1275) -> 46442 | B18: =$B$8 -> 13898.816 | C18: =E17*$E$3 -> 6052.1811 | D18: =B18-C18 -> 7846.635 | E18: =MAX(0,E17-D18) -> 518429.98 | G18: =WORKDAY.INTL(EDATE($I$2,11)-1,1,1,Feriados!$A$2:$A$1275) -> 46442 | H18: =I18+J18 -> 15750 | I18: =K17*$K$3 -> 5750 | J18: =$J$8 -> 10000 | K18: =MAX(0,K17-J18) -> 490000
A19: =WORKDAY.INTL(EDATE($C$2,12)-1,1,1,Feriados!$A$2:$A$1275) -> 46470 | B19: =$B$8 -> 13898.816 | C19: =E18*$E$3 -> 5961.9448 | D19: =B19-C19 -> 7936.8713 | E19: =MAX(0,E18-D19) -> 510493.11 | G19: =WORKDAY.INTL(EDATE($I$2,12)-1,1,1,Feriados!$A$2:$A$1275) -> 46470 | H19: =I19+J19 -> 15635 | I19: =K18*$K$3 -> 5635 | J19: =$J$8 -> 10000 | K19: =MAX(0,K18-J19) -> 480000
A20: =WORKDAY.INTL(EDATE($C$2,13)-1,1,1,Feriados!$A$2:$A$1275) -> 46503 | B20: =$B$8 -> 13898.816 | C20: =E19*$E$3 -> 5870.6707 | D20: =B20-C20 -> 8028.1454 | E20: =MAX(0,E19-D20) -> 502464.96 | G20: =WORKDAY.INTL(EDATE($I$2,13)-1,1,1,Feriados!$A$2:$A$1275) -> 46503 | H20: =I20+J20 -> 15520 | I20: =K19*$K$3 -> 5520 | J20: =$J$8 -> 10000 | K20: =MAX(0,K19-J20) -> 470000
A21: =WORKDAY.INTL(EDATE($C$2,14)-1,1,1,Feriados!$A$2:$A$1275) -> 46531 | B21: =$B$8 -> 13898.816 | C21: =E20*$E$3 -> 5778.3471 | D21: =B21-C21 -> 8120.469 | E21: =MAX(0,E20-D21) -> 494344.49 | G21: =WORKDAY.INTL(EDATE($I$2,14)-1,1,1,Feriados!$A$2:$A$1275) -> 46531 | H21: =I21+J21 -> 15405 | I21: =K20*$K$3 -> 5405 | J21: =$J$8 -> 10000 | K21: =MAX(0,K20-J21) -> 460000
A22: =WORKDAY.INTL(EDATE($C$2,15)-1,1,1,Feriados!$A$2:$A$1275) -> 46562 | B22: =$B$8 -> 13898.816 | C22: =E21*$E$3 -> 5684.9617 | D22: =B22-C22 -> 8213.8544 | E22: =MAX(0,E21-D22) -> 486130.64 | G22: =WORKDAY.INTL(EDATE($I$2,15)-1,1,1,Feriados!$A$2:$A$1275) -> 46562 | H22: =I22+J22 -> 15290 | I22: =K21*$K$3 -> 5290 | J22: =$J$8 -> 10000 | K22: =MAX(0,K21-J22) -> 450000
A23: =WORKDAY.INTL(EDATE($C$2,16)-1,1,1,Feriados!$A$2:$A$1275) -> 46594 | B23: =$B$8 -> 13898.816 | C23: =E22*$E$3 -> 5590.5023 | D23: =B23-C23 -> 8308.3138 | E23: =MAX(0,E22-D23) -> 477822.33 | G23: =WORKDAY.INTL(EDATE($I$2,16)-1,1,1,Feriados!$A$2:$A$1275) -> 46594 | H23: =I23+J23 -> 15175 | I23: =K22*$K$3 -> 5175 | J23: =$J$8 -> 10000 | K23: =MAX(0,K22-J23) -> 440000
A24: =WORKDAY.INTL(EDATE($C$2,17)-1,1,1,Feriados!$A$2:$A$1275) -> 46623 | B24: =$B$8 -> 13898.816 | C24: =E23*$E$3 -> 5494.9567 | D24: =B24-C24 -> 8403.8594 | E24: =MAX(0,E23-D24) -> 469418.47 | G24: =WORKDAY.INTL(EDATE($I$2,17)-1,1,1,Feriados!$A$2:$A$1275) -> 46623 | H24: =I24+J24 -> 15060 | I24: =K23*$K$3 -> 5060 | J24: =$J$8 -> 10000 | K24: =MAX(0,K23-J24) -> 430000
A25: =WORKDAY.INTL(EDATE($C$2,18)-1,1,1,Feriados!$A$2:$A$1275) -> 46654 | B25: =$B$8 -> 13898.816 | C25: =E24*$E$3 -> 5398.3124 | D25: =B25-C25 -> 8500.5037 | E25: =MAX(0,E24-D25) -> 460917.96 | G25: =WORKDAY.INTL(EDATE($I$2,18)-1,1,1,Feriados!$A$2:$A$1275) -> 46654 | H25: =I25+J25 -> 14945 | I25: =K24*$K$3 -> 4945 | J25: =$J$8 -> 10000 | K25: =MAX(0,K24-J25) -> 420000
A26: =WORKDAY.INTL(EDATE($C$2,19)-1,1,1,Feriados!$A$2:$A$1275) -> 46685 | B26: =$B$8 -> 13898.816 | C26: =E25*$E$3 -> 5300.5566 | D26: =B26-C26 -> 8598.2595 | E26: =MAX(0,E25-D26) -> 452319.7 | G26: =WORKDAY.INTL(EDATE($I$2,19)-1,1,1,Feriados!$A$2:$A$1275) -> 46685 | H26: =I26+J26 -> 14830 | I26: =K25*$K$3 -> 4830 | J26: =$J$8 -> 10000 | K26: =MAX(0,K25-J26) -> 410000
A27: =WORKDAY.INTL(EDATE($C$2,20)-1,1,1,Feriados!$A$2:$A$1275) -> 46715 | B27: =$B$8 -> 13898.816 | C27: =E26*$E$3 -> 5201.6766 | D27: =B27-C27 -> 8697.1395 | E27: =MAX(0,E26-D27) -> 443622.56 | G27: =WORKDAY.INTL(EDATE($I$2,20)-1,1,1,Feriados!$A$2:$A$1275) -> 46715 | H27: =I27+J27 -> 14715 | I27: =K26*$K$3 -> 4715 | J27: =$J$8 -> 10000 | K27: =MAX(0,K26-J27) -> 400000
A28: =WORKDAY.INTL(EDATE($C$2,21)-1,1,1,Feriados!$A$2:$A$1275) -> 46745 | B28: =$B$8 -> 13898.816 | C28: =E27*$E$3 -> 5101.6595 | D28: =B28-C28 -> 8797.1566 | E28: =MAX(0,E27-D28) -> 434825.41 | G28: =WORKDAY.INTL(EDATE($I$2,21)-1,1,1,Feriados!$A$2:$A$1275) -> 46745 | H28: =I28+J28 -> 14600 | I28: =K27*$K$3 -> 4600 | J28: =$J$8 -> 10000 | K28: =MAX(0,K27-J28) -> 390000
A29: =WORKDAY.INTL(EDATE($C$2,22)-1,1,1,Feriados!$A$2:$A$1275) -> 46776 | B29: =$B$8 -> 13898.816 | C29: =E28*$E$3 -> 5000.4922 | D29: =B29-C29 -> 8898.3239 | E29: =MAX(0,E28-D29) -> 425927.08 | G29: =WORKDAY.INTL(EDATE($I$2,22)-1,1,1,Feriados!$A$2:$A$1275) -> 46776 | H29: =I29+J29 -> 14485 | I29: =K28*$K$3 -> 4485 | J29: =$J$8 -> 10000 | K29: =MAX(0,K28-J29) -> 380000
A30: =WORKDAY.INTL(EDATE($C$2,23)-1,1,1,Feriados!$A$2:$A$1275) -> 46807 | B30: =$B$8 -> 13898.816 | C30: =E29*$E$3 -> 4898.1614 | D30: =B30-C30 -> 9000.6547 | E30: =MAX(0,E29-D30) -> 416926.43 | G30: =WORKDAY.INTL(EDATE($I$2,23)-1,1,1,Feriados!$A$2:$A$1275) -> 46807 | H30: =I30+J30 -> 14370 | I30: =K29*$K$3 -> 4370 | J30: =$J$8 -> 10000 | K30: =MAX(0,K29-J30) -> 370000
A31: =WORKDAY.INTL(EDATE($C$2,24)-1,1,1,Feriados!$A$2:$A$1275) -> 46836 | B31: =$B$8 -> 13898.816 | C31: =E30*$E$3 -> 4794.6539 | D31: =B31-C31 -> 9104.1622 | E31: =MAX(0,E30-D31) -> 407822.27 | G31: =WORKDAY.INTL(EDATE($I$2,24)-1,1,1,Feriados!$A$2:$A$1275) -> 46836 | H31: =I31+J31 -> 14255 | I31: =K30*$K$3 -> 4255 | J31: =$J$8 -> 10000 | K31: =MAX(0,K30-J31) -> 360000
A32: =WORKDAY.INTL(EDATE($C$2,25)-1,1,1,Feriados!$A$2:$A$1275) -> 46867 | B32: =$B$8 -> 13898.816 | C32: =E31*$E$3 -> 4689.9561 | D32: =B32-C32 -> 9208.86 | E32: =MAX(0,E31-D32) -> 398613.41 | G32: =WORKDAY.INTL(EDATE($I$2,25)-1,1,1,Feriados!$A$2:$A$1275) -> 46867 | H32: =I32+J32 -> 14140 | I32: =K31*$K$3 -> 4140 | J32: =$J$8 -> 10000 | K32: =MAX(0,K31-J32) -> 350000
A33: =WORKDAY.INTL(EDATE($C$2,26)-1,1,1,Feriados!$A$2:$A$1275) -> 46897 | B33: =$B$8 -> 13898.816 | C33: =E32*$E$3 -> 4584.0542 | D33: =B33-C33 -> 9314.7619 | E33: =MAX(0,E32-D33) -> 389298.64 | G33: =WORKDAY.INTL(EDATE($I$2,26)-1,1,1,Feriados!$A$2:$A$1275) -> 46897 | H33: =I33+J33 -> 14025 | I33: =K32*$K$3 -> 4025 | J33: =$J$8 -> 10000 | K33: =MAX(0,K32-J33) -> 340000
A34: =WORKDAY.INTL(EDATE($C$2,27)-1,1,1,Feriados!$A$2:$A$1275) -> 46930 | B34: =$B$8 -> 13898.816 | C34: =E33*$E$3 -> 4476.9344 | D34: =B34-C34 -> 9421.8817 | E34: =MAX(0,E33-D34) -> 379876.76 | G34: =WORKDAY.INTL(EDATE($I$2,27)-1,1,1,Feriados!$A$2:$A$1275) -> 46930 | H34: =I34+J34 -> 13910 | I34: =K33*$K$3 -> 3910 | J34: =$J$8 -> 10000 | K34: =MAX(0,K33-J34) -> 330000
A35: =WORKDAY.INTL(EDATE($C$2,28)-1,1,1,Feriados!$A$2:$A$1275) -> 46958 | B35: =$B$8 -> 13898.816 | C35: =E34*$E$3 -> 4368.5828 | D35: =B35-C35 -> 9530.2333 | E35: =MAX(0,E34-D35) -> 370346.53 | G35: =WORKDAY.INTL(EDATE($I$2,28)-1,1,1,Feriados!$A$2:$A$1275) -> 46958 | H35: =I35+J35 -> 13795 | I35: =K34*$K$3 -> 3795 | J35: =$J$8 -> 10000 | K35: =MAX(0,K34-J35) -> 320000
A36: =WORKDAY.INTL(EDATE($C$2,29)-1,1,1,Feriados!$A$2:$A$1275) -> 46989 | B36: =$B$8 -> 13898.816 | C36: =E35*$E$3 -> 4258.9851 | D36: =B36-C36 -> 9639.831 | E36: =MAX(0,E35-D36) -> 360706.7 | G36: =WORKDAY.INTL(EDATE($I$2,29)-1,1,1,Feriados!$A$2:$A$1275) -> 46989 | H36: =I36+J36 -> 13680 | I36: =K35*$K$3 -> 3680 | J36: =$J$8 -> 10000 | K36: =MAX(0,K35-J36) -> 310000
A37: =WORKDAY.INTL(EDATE($C$2,30)-1,1,1,Feriados!$A$2:$A$1275) -> 47021 | B37: =$B$8 -> 13898.816 | C37: =E36*$E$3 -> 4148.127 | D37: =B37-C37 -> 9750.6891 | E37: =MAX(0,E36-D37) -> 350956.01 | G37: =WORKDAY.INTL(EDATE($I$2,30)-1,1,1,Feriados!$A$2:$A$1275) -> 47021 | H37: =I37+J37 -> 13565 | I37: =K36*$K$3 -> 3565 | J37: =$J$8 -> 10000 | K37: =MAX(0,K36-J37) -> 300000
A38: =WORKDAY.INTL(EDATE($C$2,31)-1,1,1,Feriados!$A$2:$A$1275) -> 47050 | B38: =$B$8 -> 13898.816 | C38: =E37*$E$3 -> 4035.9941 | D38: =B38-C38 -> 9862.822 | E38: =MAX(0,E37-D38) -> 341093.19 | G38: =WORKDAY.INTL(EDATE($I$2,31)-1,1,1,Feriados!$A$2:$A$1275) -> 47050 | H38: =I38+J38 -> 13450 | I38: =K37*$K$3 -> 3450 | J38: =$J$8 -> 10000 | K38: =MAX(0,K37-J38) -> 290000
A39: =WORKDAY.INTL(EDATE($C$2,32)-1,1,1,Feriados!$A$2:$A$1275) -> 47081 | B39: =$B$8 -> 13898.816 | C39: =E38*$E$3 -> 3922.5716 | D39: =B39-C39 -> 9976.2445 | E39: =MAX(0,E38-D39) -> 331116.94 | G39: =WORKDAY.INTL(EDATE($I$2,32)-1,1,1,Feriados!$A$2:$A$1275) -> 47081 | H39: =I39+J39 -> 13335 | I39: =K38*$K$3 -> 3335 | J39: =$J$8 -> 10000 | K39: =MAX(0,K38-J39) -> 280000
A40: =WORKDAY.INTL(EDATE($C$2,33)-1,1,1,Feriados!$A$2:$A$1275) -> 47113 | B40: =$B$8 -> 13898.816 | C40: =E39*$E$3 -> 3807.8448 | D40: =B40-C40 -> 10090.971 | E40: =MAX(0,E39-D40) -> 321025.97 | G40: =WORKDAY.INTL(EDATE($I$2,33)-1,1,1,Feriados!$A$2:$A$1275) -> 47113 | H40: =I40+J40 -> 13220 | I40: =K39*$K$3 -> 3220 | J40: =$J$8 -> 10000 | K40: =MAX(0,K39-J40) -> 270000
A41: =WORKDAY.INTL(EDATE($C$2,34)-1,1,1,Feriados!$A$2:$A$1275) -> 47142 | B41: =$B$8 -> 13898.816 | C41: =E40*$E$3 -> 3691.7987 | D41: =B41-C41 -> 10207.017 | E41: =MAX(0,E40-D41) -> 310818.95 | G41: =WORKDAY.INTL(EDATE($I$2,34)-1,1,1,Feriados!$A$2:$A$1275) -> 47142 | H41: =I41+J41 -> 13105 | I41: =K40*$K$3 -> 3105 | J41: =$J$8 -> 10000 | K41: =MAX(0,K40-J41) -> 260000
A42: =WORKDAY.INTL(EDATE($C$2,35)-1,1,1,Feriados!$A$2:$A$1275) -> 47175 | B42: =$B$8 -> 13898.816 | C42: =E41*$E$3 -> 3574.418 | D42: =B42-C42 -> 10324.398 | E42: =MAX(0,E41-D42) -> 300494.55 | G42: =WORKDAY.INTL(EDATE($I$2,35)-1,1,1,Feriados!$A$2:$A$1275) -> 47175 | H42: =I42+J42 -> 12990 | I42: =K41*$K$3 -> 2990 | J42: =$J$8 -> 10000 | K42: =MAX(0,K41-J42) -> 250000
A43: =WORKDAY.INTL(EDATE($C$2,36)-1,1,1,Feriados!$A$2:$A$1275) -> 47203 | B43: =$B$8 -> 13898.816 | C43: =E42*$E$3 -> 3455.6874 | D43: =B43-C43 -> 10443.129 | E43: =MAX(0,E42-D43) -> 290051.43 | G43: =WORKDAY.INTL(EDATE($I$2,36)-1,1,1,Feriados!$A$2:$A$1275) -> 47203 | H43: =I43+J43 -> 12875 | I43: =K42*$K$3 -> 2875 | J43: =$J$8 -> 10000 | K43: =MAX(0,K42-J43) -> 240000
...

Sheet Avaliação de Projeto
A2: Avaliação de Projeto de Investimento | M2: Premissas auxiliares
M3: Receita base Ano 1 | N3: 80250000
A4: Alíquota Média ICMS | B4: 0.07 | D4: g1 | E4: 0.044 | G4: c1 | H4: 0.042 | M4: CMV base Ano 1 | N4: 52450000
A5: Alíquota PIS | B5: 0.0165 | D5: g2 | E5: 0.05 | G5: c2 | H5: 0.052 | M5: Salários base Ano 1 | N5: 4000000
A6: Alíquota COFINS | B6: 0.076 | D6: g3 | E6: 0.053 | G6: c3 | H6: 0.055 | M6: Reajuste salarial | N6: 0.05
A7: Serviços Gerais e Adminstração | B7: 0.022 | D7: CM | M7: Vida útil imóvel (anos) | N7: 10
A8: Aluguéis e Condomínios | B8: 0.02 | D8: TMA | E8: 0.158 | M8: Depreciação anual | N8: =E10/N7 -> 850000
A9: Propaganda e Publicidade | B9: 0.03 | M9: Premissa: imóvel depreciado em 25 anos (4% a.a.)
A10: Despesas Comerciais e Comissões | B10: 0.025 | D10: Valor do Imóvel | E10: 8500000
A11: Imposto de Renda e CSSL | B11: 0.34 | D11: Investimento | E11: 10000000
B14: Ano 1 | C14: Ano 2 | D14: Ano 3 | E14: Ano 4 | F14: Ano 5 | G14: Ano 6 | H14: Ano 7 | I14: Ano 8 | J14: Ano 9 | K14: Ano 10
A15: 1. Receita de Vendas | B15: =$N$3 -> 80250000 | C15: =B15*(1+$E$4) -> 83781000 | D15: =C15*(1+$E$4) -> 87467364 | E15: =D15*(1+$E$5) -> 91840732 | F15: =E15*(1+$E$5) -> 96432769 | G15: =F15*(1+$E$5) -> 1.0125441e+08 | H15: =G15*(1+$E$6) -> 1.0662089e+08 | I15: =H15*(1+$E$6) -> 1.122718e+08 | J15: =I15*(1+$E$6) -> 1.182222e+08 | K15: =J15*(1+$E$6) -> 1.2448798e+08
A16: 2. Impostos sobre Vendas | B16: =SUM(B17:B19) -> 12521006 | C16: =SUM(C17:C19) -> 13071931 | D16: =SUM(D17:D19) -> 13647095 | E16: =SUM(E17:E19) -> 14329450 | F16: =SUM(F17:F19) -> 15045923 | G16: =SUM(G17:G19) -> 15798219 | H16: =SUM(H17:H19) -> 16635524 | I16: =SUM(I17:I19) -> 17517207 | ... K16: =SUM(K17:K19) -> 19423237
A17: 2.1. ICMS | B17: =B15*$B$4 -> 5617500 | C17: =C15*$B$4 -> 5864670 | D17: =D15*$B$4 -> 6122715.5 | E17: =E15*$B$4 -> 6428851.3 | F17: =F15*$B$4 -> 6750293.8 | G17: =G15*$B$4 -> 7087808.5 | H17: =H15*$B$4 -> 7463462.4 | I17: =I15*$B$4 -> 7859025.9 | ... K17: =K15*$B$4 -> 8714158.6
A18: 2.2. PIS | B18: =(B15-B17)*$B$5 -> 1231436.2 | C18: =(C15-C17)*$B$5 -> 1285619.4 | D18: =(D15-D17)*$B$5 -> 1342186.7 | E18: =(E15-E17)*$B$5 -> 1409296 | F18: =(F15-F17)*$B$5 -> 1479760.8 | G18: =(G15-G17)*$B$5 -> 1553748.9 | H18: =(H15-H17)*$B$5 -> 1636097.6 | I18: =(I15-I17)*$B$5 -> 1722810.7 | ... K18: =(K15-K17)*$B$5 -> 1910268.1
A19: 2.3. COFINS | B19: =(B15-B17)*$B$6 -> 5672070 | C19: =(C15-C17)*$B$6 -> 5921641.1 | D19: =(D15-D17)*$B$6 -> 6182193.3 | E19: =(E15-E17)*$B$6 -> 6491303 | F19: =(F15-F17)*$B$6 -> 6815868.1 | G19: =(G15-G17)*$B$6 -> 7156661.5 | H19: =(H15-H17)*$B$6 -> 7535964.6 | I19: =(I15-I17)*$B$6 -> 7935370.7 | ... K19: =(K15-K17)*$B$6 -> 8798810.4
A20: 3. Receita Líquida | B20: =B15-B16 -> 67728994 | C20: =C15-C16 -> 70709069 | D20: =D15-D16 -> 73820269 | E20: =E15-E16 -> 77511282 | F20: =F15-F16 -> 81386846 | G20: =G15-G16 -> 85456188 | H20: =H15-H16 -> 89985366 | I20: =I15-I16 -> 94754591 | ... K20: =K15-K16 -> 1.0506474e+08
A21: 4. Custo de Mercadoria Vendida | B21: =$N$4 -> 52450000 | C21: =B21*(1+$H$4) -> 54652900 | D21: =C21*(1+$H$4) -> 56948322 | E21: =D21*(1+$H$5) -> 59909635 | F21: =E21*(1+$H$5) -> 63024936 | G21: =F21*(1+$H$5) -> 66302232 | H21: =G21*(1+$H$6) -> 69948855 | I21: =H21*(1+$H$6) -> 73796042 | J21: =I21*(1+$H$6) -> 77854824 | K21: =J21*(1+$H$6) -> 82136840
A22: 5. Despesas Operacionais | B22: =SUM(B23:B27) -> 11784250 | C22: =SUM(C23:C27) -> 12326757 | D22: =SUM(D23:D27) -> 12894334 | E22: =SUM(E23:E27) -> 13539051 | F22: =SUM(F23:F27) -> 14216004 | G22: =SUM(G23:G27) -> 14926804 | H22: =SUM(H23:H27) -> 15702609 | I22: =SUM(I23:I27) -> 16518766 | ... K22: =SUM(K23:K27) -> 18280647
A23: 5.1. Despesas com Salários e Encargos | B23: =$N$5 -> 4000000 | C23: =B23*(1+$N$6) -> 4200000 | D23: =C23*(1+$N$6) -> 4410000 | E23: =D23*(1+$N$6) -> 4630500 | F23: =E23*(1+$N$6) -> 4862025 | G23: =F23*(1+$N$6) -> 5105126.2 | H23: =G23*(1+$N$6) -> 5360382.6 | I23: =H23*(1+$N$6) -> 5628401.7 | J23: =I23*(1+$N$6) -> 5909821.8 | K23: =J23*(1+$N$6) -> 6205312.9
A24: 5.2. Serviços Gerais e Administração | B24: =B15*$B$7 -> 1765500 | C24: =C15*$B$7 -> 1843182 | D24: =D15*$B$7 -> 1924282 | E24: =E15*$B$7 -> 2020496.1 | F24: =F15*$B$7 -> 2121520.9 | G24: =G15*$B$7 -> 2227597 | H24: =H15*$B$7 -> 2345659.6 | I24: =I15*$B$7 -> 2469979.6 | ... K24: =K15*$B$7 -> 2738735.6
A25: 5.3. Despesas de Aluguéis e Condomínios | B25: =B15*$B$8 -> 1605000 | C25: =C15*$B$8 -> 1675620 | D25: =D15*$B$8 -> 1749347.3 | E25: =E15*$B$8 -> 1836814.6 | F25: =F15*$B$8 -> 1928655.4 | G25: =G15*$B$8 -> 2025088.1 | H25: =H15*$B$8 -> 2132417.8 | I25: =I15*$B$8 -> 2245436 | ... K25: =K15*$B$8 -> 2489759.6
A26: 5.4. Despesas de Propaganda e Publicidade | B26: =B15*$B$9 -> 2407500 | C26: =C15*$B$9 -> 2513430 | D26: =D15*$B$9 -> 2624020.9 | E26: =E15*$B$9 -> 2755222 | F26: =F15*$B$9 -> 2892983.1 | G26: =G15*$B$9 -> 3037632.2 | H26: =H15*$B$9 -> 3198626.7 | I26: =I15*$B$9 -> 3368153.9 | ... K26: =K15*$B$9 -> 3734639.4
A27: 5.5. Despesas Comerciais e Comissões | B27: =B15*$B$10 -> 2006250 | C27: =C15*$B$10 -> 2094525 | D27: =D15*$B$10 -> 2186684.1 | E27: =E15*$B$10 -> 2296018.3 | F27: =F15*$B$10 -> 2410819.2 | G27: =G15*$B$10 -> 2531360.2 | H27: =H15*$B$10 -> 2665522.3 | I27: =I15*$B$10 -> 2806795 | ... K27: =K15*$B$10 -> 3112199.5
A28: 6. EBITDA | B28: =B20-B21-B22 -> 3494743.8 | C28: =C20-C21-C22 -> 3729412.5 | D28: =D20-D21-D22 -> 3977612.4 | E28: =E20-E21-E22 -> 4062596.4 | F28: =F20-F21-F22 -> 4145907 | G28: =G20-G21-G22 -> 4227152.4 | H28: =H20-H21-H22 -> 4333902.4 | I28: =I20-I21-I22 -> 4439782.7 | ... K28: =K20-K21-K22 -> 4647256.5
A29: 7. Margem EBITDA | B29: =IFERROR(B28/B20,0) -> 0.051598932 | C29: =IFERROR(C28/C20,0) -> 0.052743057 | D29: =IFERROR(D28/D20,0) -> 0.053882389 | E29: =IFERROR(E28/E20,0) -> 0.052412969 | F29: =IFERROR(F28/F20,0) -> 0.05094075 | G29: =IFERROR(G28/G20,0) -> 0.049465726 | H29: =IFERROR(H28/H20,0) -> 0.048162302 | I29: =IFERROR(I28/I20,0) -> 0.046855595 | ... K29: =IFERROR(K28/K20,0) -> 0.044232312
A30: 8. Depreciação e Amortização | B30: =$N$8 -> 850000 | C30: =$N$8 -> 850000 | D30: =$N$8 -> 850000 | E30: =$N$8 -> 850000 | F30: =$N$8 -> 850000 | G30: =$N$8 -> 850000 | H30: =$N$8 -> 850000 | I30: =$N$8 -> 850000 | ... K30: =$N$8 -> 850000
A31: 9. Despesas Financeiras | B31: =SUM(Financiamento!C10:C21) -> 913137.5 | C31: =SUM(Financiamento!C22:C33) -> 817437.5 | D31: =SUM(Financiamento!C34:C45) -> 721737.5 | E31: =SUM(Financiamento!C46:C57) -> 626037.5 | F31: =SUM(Financiamento!C58:C69) -> 530337.5 | G31: =SUM(Financiamento!C70:C81) -> 434637.5 | H31: =SUM(Financiamento!C82:C93) -> 338937.5 | I31: =SUM(Financiamento!C94:C105) -> 243237.5 | J31: =SUM(Financiamento!C106:C117) -> 147537.5 | K31: =SUM(Financiamento!C118:C129) -> 51837.5
A32: 10. Lucro antes do IR | B32: =B28-B30-B31 -> 1731606.2 | C32: =C28-C30-C31 -> 2061975 | D32: =D28-D30-D31 -> 2405874.9 | E32: =E28-E30-E31 -> 2586558.9 | F32: =F28-F30-F31 -> 2765569.5 | G32: =G28-G30-G31 -> 2942514.9 | H32: =H28-H30-H31 -> 3144964.9 | I32: =I28-I30-I31 -> 3346545.2 | ... K32: =K28-K30-K31 -> 3745419
A33: 11. IR e CSSL | B33: =IF(B32>0,B32*$B$11,0) -> 588746.12 | C33: =IF(C32>0,C32*$B$11,0) -> 701071.49 | D33: =IF(D32>0,D32*$B$11,0) -> 817997.47 | E33: =IF(E32>0,E32*$B$11,0) -> 879430.03 | F33: =IF(F32>0,F32*$B$11,0) -> 940293.61 | G33: =IF(G32>0,G32*$B$11,0) -> 1000455.1 | H33: =IF(H32>0,H32*$B$11,0) -> 1069288.1 | I33: =IF(I32>0,I32*$B$11,0) -> 1137825.4 | ... K33: =IF(K32>0,K32*$B$11,0) -> 1273442.5
A34: 12. Fluxo de Caixa | B34: =B32-B33+B30 -> 1992860.1 | C34: =C32-C33+C30 -> 2210903.5 | D34: =D32-D33+D30 -> 2437877.4 | E34: =E32-E33+E30 -> 2557128.9 | F34: =F32-F33+F30 -> 2675275.8 | G34: =G32-G33+G30 -> 2792059.9 | H34: =H32-H33+H30 -> 2925676.8 | I34: =I32-I33+I30 -> 3058719.8 | ... K34: =K32-K33+K30 -> 3321976.5
A37: Investimento | B37: Ano 1 | C37: Ano 2 | D37: Ano 3 | E37: Ano 4 | F37: Ano 5 | G37: Ano 6 | H37: Ano 7 | I37: Ano 8 | J37: Ano 9 | K37: Ano 10
A38: =-$E$11 -> -10000000 | B38: =B34 -> 1992860.1 | C38: =C34 -> 2210903.5 | D38: =D34 -> 2437877.4 | E38: =E34 -> 2557128.9 | F38: =F34 -> 2675275.8 | G38: =G34 -> 2792059.9 | H38: =H34 -> 2925676.8 | I38: =I34 -> 3058719.8 | ... K38: =K34 -> 3321976.5
A39: Fluxo Descontado | B39: =B34/(1+$E$8)^1 -> 1720950 | C39: =C34/(1+$E$8)^2 -> 1648741.9 | D39: =D34/(1+$E$8)^3 -> 1569951.3 | E39: =E34/(1+$E$8)^4 -> 1422061.5 | F39: =F34/(1+$E$8)^5 -> 1284771.1 | G39: =G34/(1+$E$8)^6 -> 1157906.2 | H39: =H34/(1+$E$8)^7 -> 1047771.2 | I39: =I34/(1+$E$8)^8 -> 945956.62 | J39: =J34/(1+$E$8)^9 -> 852194.5 | K39: =K34/(1+$E$8)^10 -> 766144.99
A40: Fluxo Descontado Acumulado | B40: =$A$38+B39 -> -8279050 | C40: =B40+C39 -> -6630308.1 | D40: =C40+D39 -> -5060356.8 | E40: =D40+E39 -> -3638295.3 | F40: =E40+F39 -> -2353524.1 | G40: =F40+G39 -> -1195618 | H40: =G40+H39 -> -147846.81 | I40: =H40+I39 -> 798109.81 | J40: =I40+J39 -> 1650304.3 | K40: =J40+K39 -> 2416449.3
A41: Taxa Mínima de Atratividade - TMA | B41: =$E$8 -> 0.158
A42: Taxa Interna de Retorno - TIR | B42: =IRR(A38:K38) -> 0.21411917
A43: Valor Presente Líquido - VPL | B43: =NPV(B41,B38:K38)+A38 -> 2416449.3
A44: Payback Descontado - PBD | B44: =IF(K40<0,"Não recupera em 10 anos",MATCH(TRUE(),INDEX(B40:K40>=0,0),0)-1+ABS(INDEX(B40:K40,MATCH(TRUE(),INDEX(B40:K40>=0,0),0)-1))/INDEX(B39:K39,MATCH(TRUE(),INDEX(B40:K40>=0,0),0))) -> 7.1562934
A45: Valor Presente - VP | B45: =SUM(B39:K39) -> 12416449

Sheet Financiamento
B4: PV | C4: 7250000
B5: TAXA | C5: 0.011
B6: NPER | C6: 120
A8: PERÍODO | B8: PRESTAÇÃO | C8: JUROS | D8: AMORTIZAÇÃO | E8: SALDO DEVEDOR
A9: 0 | B9: 0 | C9: 0 | D9: 0 | E9: =$C$4 -> 7250000
A10: 1 | B10: =C10+D10 -> 140166.67 | C10: =E9*$C$5 -> 79750 | D10: =$C$4/$C$6 -> 60416.667 | E10: =MAX(0,E9-D10) -> 7189583.3
A11: 2 | B11: =C11+D11 -> 139502.08 | C11: =E10*$C$5 -> 79085.417 | D11: =$C$4/$C$6 -> 60416.667 | E11: =MAX(0,E10-D11) -> 7129166.7
A12: 3 | B12: =C12+D12 -> 138837.5 | C12: =E11*$C$5 -> 78420.833 | D12: =$C$4/$C$6 -> 60416.667 | E12: =MAX(0,E11-D12) -> 7068750
A13: 4 | B13: =C13+D13 -> 138172.92 | C13: =E12*$C$5 -> 77756.25 | D13: =$C$4/$C$6 -> 60416.667 | E13: =MAX(0,E12-D13) -> 7008333.3
A14: 5 | B14: =C14+D14 -> 137508.33 | C14: =E13*$C$5 -> 77091.667 | D14: =$C$4/$C$6 -> 60416.667 | E14: =MAX(0,E13-D14) -> 6947916.7
A15: 6 | B15: =C15+D15 -> 136843.75 | C15: =E14*$C$5 -> 76427.083 | D15: =$C$4/$C$6 -> 60416.667 | E15: =MAX(0,E14-D15) -> 6887500
A16: 7 | B16: =C16+D16 -> 136179.17 | C16: =E15*$C$5 -> 75762.5 | D16: =$C$4/$C$6 -> 60416.667 | E16: =MAX(0,E15-D16) -> 6827083.3
A17: 8 | B17: =C17+D17 -> 135514.58 | C17: =E16*$C$5 -> 75097.917 | D17: =$C$4/$C$6 -> 60416.667 | E17: =MAX(0,E16-D17) -> 6766666.7
A18: 9 | B18: =C18+D18 -> 134850 | C18: =E17*$C$5 -> 74433.333 | D18: =$C$4/$C$6 -> 60416.667 | E18: =MAX(0,E17-D18) -> 6706250
A19: 10 | B19: =C19+D19 -> 134185.42 | C19: =E18*$C$5 -> 73768.75 | D19: =$C$4/$C$6 -> 60416.667 | E19: =MAX(0,E18-D19) -> 6645833.3
A20: 11 | B20: =C20+D20 -> 133520.83 | C20: =E19*$C$5 -> 73104.167 | D20: =$C$4/$C$6 -> 60416.667 | E20: =MAX(0,E19-D20) -> 6585416.7
A21: 12 | B21: =C21+D21 -> 132856.25 | C21: =E20*$C$5 -> 72439.583 | D21: =$C$4/$C$6 -> 60416.667 | E21: =MAX(0,E20-D21) -> 6525000
... A129: 120 | B129: =C129+D129 -> 61081.25 | C129: =E128*$C$5 -> 664.58333 | D129: =$C$4/$C$6 -> 60416.667 | E129: =MAX(0,E128-D129) -> 0
